2025-05-25 11:00:38,752 INFO    MainThread:1182312 [wandb_setup.py:_flush():67] Current SDK version is 0.19.9
2025-05-25 11:00:38,752 INFO    MainThread:1182312 [wandb_setup.py:_flush():67] Configure stats pid to 1182312
2025-05-25 11:00:38,752 INFO    MainThread:1182312 [wandb_setup.py:_flush():67] Loading settings from /home/hawk/.config/wandb/settings
2025-05-25 11:00:38,752 INFO    MainThread:1182312 [wandb_setup.py:_flush():67] Loading settings from /home/hawk/Desktop/Heavy-Clutter-Detection/Thesis/wandb/settings
2025-05-25 11:00:38,752 INFO    MainThread:1182312 [wandb_setup.py:_flush():67] Loading settings from environment variables
2025-05-25 11:00:38,752 INFO    MainThread:1182312 [wandb_init.py:setup_run_log_directory():662] Logging user logs to /home/hawk/Desktop/Heavy-Clutter-Detection/Thesis/wandb/run-20250525_110038-71e6h2k4/logs/debug.log
2025-05-25 11:00:38,752 INFO    MainThread:1182312 [wandb_init.py:setup_run_log_directory():663] Logging internal logs to /home/hawk/Desktop/Heavy-Clutter-Detection/Thesis/wandb/run-20250525_110038-71e6h2k4/logs/debug-internal.log
2025-05-25 11:00:38,752 INFO    MainThread:1182312 [wandb_init.py:monkeypatch_ipython():581] configuring jupyter hooks <wandb.sdk.wandb_init._WandbInit object at 0x7cc902938140>
2025-05-25 11:00:38,753 INFO    MainThread:1182312 [wandb_init.py:init():781] calling init triggers
2025-05-25 11:00:38,753 INFO    MainThread:1182312 [wandb_init.py:init():786] wandb.init called with sweep_config: {}
config: {'SNR': [10], 'CNR': [15], 'NU': [0.2, 0.5, 1.0], 'n_targets': 8, 'rand_n_targets': True, 'beta_end': 0.01, 'beta_start': 0.0001, 'batch_size': 16, 'num_epochs': 400, 'noise_steps': 2000, 'num_workers': 4, 'dataset_size': 50000, 'time_emb_dim': 256, 'learning_rate': 0.0001, 'scheduler_type': 'cosine', '_wandb': {}}
2025-05-25 11:00:38,753 INFO    MainThread:1182312 [wandb_init.py:init():809] starting backend
2025-05-25 11:00:38,753 INFO    MainThread:1182312 [wandb_init.py:init():813] sending inform_init request
2025-05-25 11:00:38,756 INFO    MainThread:1182312 [backend.py:_multiprocessing_setup():101] multiprocessing start_methods=fork,spawn,forkserver, using: spawn
2025-05-25 11:00:38,756 INFO    MainThread:1182312 [wandb_init.py:init():823] backend started and connected
2025-05-25 11:00:38,758 INFO    MainThread:1182312 [wandb_run.py:_label_probe_notebook():1267] probe notebook
2025-05-25 11:00:38,767 INFO    MainThread:1182312 [wandb_init.py:init():915] updated telemetry
2025-05-25 11:00:38,771 INFO    MainThread:1182312 [wandb_init.py:init():939] communicating run to backend with 90.0 second timeout
2025-05-25 11:01:06,450 WARNING MainThread:1182312 [wandb_init.py:init():1534] [no run ID] interrupted
Traceback (most recent call last):
  File "/home/hawk/Desktop/Heavy-Clutter-Detection/finalDiffusion/.venv/lib/python3.12/site-packages/wandb/sdk/wandb_init.py", line 1530, in init
    return wi.init(run_settings, run_config)
           ^^^^^^^^^^^^^^^^^^^^^^^^^^^^^^^^^
  File "/home/hawk/Desktop/Heavy-Clutter-Detection/finalDiffusion/.venv/lib/python3.12/site-packages/wandb/sdk/wandb_init.py", line 965, in init
    result = wait_with_progress(
             ^^^^^^^^^^^^^^^^^^^
  File "/home/hawk/Desktop/Heavy-Clutter-Detection/finalDiffusion/.venv/lib/python3.12/site-packages/wandb/sdk/mailbox/wait_with_progress.py", line 24, in wait_with_progress
    return wait_all_with_progress(
           ^^^^^^^^^^^^^^^^^^^^^^^
  File "/home/hawk/Desktop/Heavy-Clutter-Detection/finalDiffusion/.venv/lib/python3.12/site-packages/wandb/sdk/mailbox/wait_with_progress.py", line 87, in wait_all_with_progress
    return asyncio_compat.run(progress_loop_with_timeout)
           ^^^^^^^^^^^^^^^^^^^^^^^^^^^^^^^^^^^^^^^^^^^^^^
  File "/home/hawk/Desktop/Heavy-Clutter-Detection/finalDiffusion/.venv/lib/python3.12/site-packages/wandb/sdk/lib/asyncio_compat.py", line 30, in run
    return future.result()
           ^^^^^^^^^^^^^^^
  File "/usr/lib/python3.12/concurrent/futures/_base.py", line 451, in result
    self._condition.wait(timeout)
  File "/usr/lib/python3.12/threading.py", line 355, in wait
    waiter.acquire()
KeyboardInterrupt
2025-05-25 11:01:06,452 WARNING MsgRouterThr:1182312 [router.py:message_loop():63] [no run ID] message_loop has been closed
Traceback (most recent call last):
  File "/home/hawk/Desktop/Heavy-Clutter-Detection/finalDiffusion/.venv/lib/python3.12/site-packages/wandb/sdk/interface/router_sock.py", line 27, in _read_message
    return self._sock_client.read_server_response(timeout=1)
           ^^^^^^^^^^^^^^^^^^^^^^^^^^^^^^^^^^^^^^^^^^^^^^^^^
  File "/home/hawk/Desktop/Heavy-Clutter-Detection/finalDiffusion/.venv/lib/python3.12/site-packages/wandb/sdk/lib/sock_client.py", line 235, in read_server_response
    data = self._read_packet_bytes(timeout=timeout)
           ^^^^^^^^^^^^^^^^^^^^^^^^^^^^^^^^^^^^^^^^
  File "/home/hawk/Desktop/Heavy-Clutter-Detection/finalDiffusion/.venv/lib/python3.12/site-packages/wandb/sdk/lib/sock_client.py", line 220, in _read_packet_bytes
    raise SockClientClosedError
wandb.sdk.lib.sock_client.SockClientClosedError

The above exception was the direct cause of the following exception:

Traceback (most recent call last):
  File "/home/hawk/Desktop/Heavy-Clutter-Detection/finalDiffusion/.venv/lib/python3.12/site-packages/wandb/sdk/interface/router.py", line 56, in message_loop
    msg = self._read_message()
          ^^^^^^^^^^^^^^^^^^^^
  File "/home/hawk/Desktop/Heavy-Clutter-Detection/finalDiffusion/.venv/lib/python3.12/site-packages/wandb/sdk/interface/router_sock.py", line 29, in _read_message
    raise MessageRouterClosedError from e
wandb.sdk.interface.router.MessageRouterClosedError
2025-05-25 11:01:06,549 INFO    MsgRouterThr:1182312 [mailbox.py:close():129] [no run ID] Closing mailbox, abandoning 2 handles.
2025-05-25 11:02:31,724 INFO    Thread-14 (wrapped_target):1182312 [retry.py:__call__():175] [no run ID] Retry attempt failed:
Traceback (most recent call last):
  File "/home/hawk/Desktop/Heavy-Clutter-Detection/finalDiffusion/.venv/lib/python3.12/site-packages/urllib3/connection.py", line 198, in _new_conn
    sock = connection.create_connection(
           ^^^^^^^^^^^^^^^^^^^^^^^^^^^^^
  File "/home/hawk/Desktop/Heavy-Clutter-Detection/finalDiffusion/.venv/lib/python3.12/site-packages/urllib3/util/connection.py", line 85, in create_connection
    raise err
  File "/home/hawk/Desktop/Heavy-Clutter-Detection/finalDiffusion/.venv/lib/python3.12/site-packages/urllib3/util/connection.py", line 73, in create_connection
    sock.connect(sa)
ConnectionRefusedError: [Errno 111] Connection refused

The above exception was the direct cause of the following exception:

Traceback (most recent call last):
  File "/home/hawk/Desktop/Heavy-Clutter-Detection/finalDiffusion/.venv/lib/python3.12/site-packages/urllib3/connectionpool.py", line 787, in urlopen
    response = self._make_request(
               ^^^^^^^^^^^^^^^^^^^
  File "/home/hawk/Desktop/Heavy-Clutter-Detection/finalDiffusion/.venv/lib/python3.12/site-packages/urllib3/connectionpool.py", line 493, in _make_request
    conn.request(
  File "/home/hawk/Desktop/Heavy-Clutter-Detection/finalDiffusion/.venv/lib/python3.12/site-packages/urllib3/connection.py", line 445, in request
    self.endheaders()
  File "/usr/lib/python3.12/http/client.py", line 1331, in endheaders
    self._send_output(message_body, encode_chunked=encode_chunked)
  File "/usr/lib/python3.12/http/client.py", line 1091, in _send_output
    self.send(msg)
  File "/usr/lib/python3.12/http/client.py", line 1035, in send
    self.connect()
  File "/home/hawk/Desktop/Heavy-Clutter-Detection/finalDiffusion/.venv/lib/python3.12/site-packages/urllib3/connection.py", line 276, in connect
    self.sock = self._new_conn()
                ^^^^^^^^^^^^^^^^
  File "/home/hawk/Desktop/Heavy-Clutter-Detection/finalDiffusion/.venv/lib/python3.12/site-packages/urllib3/connection.py", line 213, in _new_conn
    raise NewConnectionError(
urllib3.exceptions.NewConnectionError: <urllib3.connection.HTTPConnection object at 0x7cc8fcdf3290>: Failed to establish a new connection: [Errno 111] Connection refused

The above exception was the direct cause of the following exception:

Traceback (most recent call last):
  File "/home/hawk/Desktop/Heavy-Clutter-Detection/finalDiffusion/.venv/lib/python3.12/site-packages/requests/adapters.py", line 667, in send
    resp = conn.urlopen(
           ^^^^^^^^^^^^^
  File "/home/hawk/Desktop/Heavy-Clutter-Detection/finalDiffusion/.venv/lib/python3.12/site-packages/urllib3/connectionpool.py", line 841, in urlopen
    retries = retries.increment(
              ^^^^^^^^^^^^^^^^^^
  File "/home/hawk/Desktop/Heavy-Clutter-Detection/finalDiffusion/.venv/lib/python3.12/site-packages/urllib3/util/retry.py", line 519, in increment
    raise MaxRetryError(_pool, url, reason) from reason  # type: ignore[arg-type]
    ^^^^^^^^^^^^^^^^^^^^^^^^^^^^^^^^^^^^^^^^^^^^^^^^^^^
urllib3.exceptions.MaxRetryError: HTTPConnectionPool(host='127.0.0.1', port=8081): Max retries exceeded with url: /graphql (Caused by NewConnectionError('<urllib3.connection.HTTPConnection object at 0x7cc8fcdf3290>: Failed to establish a new connection: [Errno 111] Connection refused'))

During handling of the above exception, another exception occurred:

Traceback (most recent call last):
  File "/home/hawk/Desktop/Heavy-Clutter-Detection/finalDiffusion/.venv/lib/python3.12/site-packages/wandb/sdk/lib/retry.py", line 134, in __call__
    result = self._call_fn(*args, **kwargs)
             ^^^^^^^^^^^^^^^^^^^^^^^^^^^^^^
  File "/home/hawk/Desktop/Heavy-Clutter-Detection/finalDiffusion/.venv/lib/python3.12/site-packages/wandb/sdk/internal/internal_api.py", line 402, in execute
    return self.client.execute(*args, **kwargs)  # type: ignore
           ^^^^^^^^^^^^^^^^^^^^^^^^^^^^^^^^^^^^
  File "/home/hawk/Desktop/Heavy-Clutter-Detection/finalDiffusion/.venv/lib/python3.12/site-packages/wandb/vendor/gql-0.2.0/wandb_gql/client.py", line 52, in execute
    result = self._get_result(document, *args, **kwargs)
             ^^^^^^^^^^^^^^^^^^^^^^^^^^^^^^^^^^^^^^^^^^^
  File "/home/hawk/Desktop/Heavy-Clutter-Detection/finalDiffusion/.venv/lib/python3.12/site-packages/wandb/vendor/gql-0.2.0/wandb_gql/client.py", line 60, in _get_result
    return self.transport.execute(document, *args, **kwargs)
           ^^^^^^^^^^^^^^^^^^^^^^^^^^^^^^^^^^^^^^^^^^^^^^^^^
  File "/home/hawk/Desktop/Heavy-Clutter-Detection/finalDiffusion/.venv/lib/python3.12/site-packages/wandb/sdk/lib/gql_request.py", line 58, in execute
    request = self.session.post(self.url, **post_args)
              ^^^^^^^^^^^^^^^^^^^^^^^^^^^^^^^^^^^^^^^^
  File "/home/hawk/Desktop/Heavy-Clutter-Detection/finalDiffusion/.venv/lib/python3.12/site-packages/requests/sessions.py", line 637, in post
    return self.request("POST", url, data=data, json=json, **kwargs)
           ^^^^^^^^^^^^^^^^^^^^^^^^^^^^^^^^^^^^^^^^^^^^^^^^^^^^^^^^^
  File "/home/hawk/Desktop/Heavy-Clutter-Detection/finalDiffusion/.venv/lib/python3.12/site-packages/requests/sessions.py", line 589, in request
    resp = self.send(prep, **send_kwargs)
           ^^^^^^^^^^^^^^^^^^^^^^^^^^^^^^
  File "/home/hawk/Desktop/Heavy-Clutter-Detection/finalDiffusion/.venv/lib/python3.12/site-packages/requests/sessions.py", line 703, in send
    r = adapter.send(request, **kwargs)
        ^^^^^^^^^^^^^^^^^^^^^^^^^^^^^^^
  File "/home/hawk/Desktop/Heavy-Clutter-Detection/finalDiffusion/.venv/lib/python3.12/site-packages/requests/adapters.py", line 700, in send
    raise ConnectionError(e, request=request)
requests.exceptions.ConnectionError: HTTPConnectionPool(host='127.0.0.1', port=8081): Max retries exceeded with url: /graphql (Caused by NewConnectionError('<urllib3.connection.HTTPConnection object at 0x7cc8fcdf3290>: Failed to establish a new connection: [Errno 111] Connection refused'))
2025-05-25 11:02:36,087 INFO    Thread-14 (wrapped_target):1182312 [retry.py:__call__():175] [no run ID] Retry attempt failed:
Traceback (most recent call last):
  File "/home/hawk/Desktop/Heavy-Clutter-Detection/finalDiffusion/.venv/lib/python3.12/site-packages/urllib3/connection.py", line 198, in _new_conn
    sock = connection.create_connection(
           ^^^^^^^^^^^^^^^^^^^^^^^^^^^^^
  File "/home/hawk/Desktop/Heavy-Clutter-Detection/finalDiffusion/.venv/lib/python3.12/site-packages/urllib3/util/connection.py", line 85, in create_connection
    raise err
  File "/home/hawk/Desktop/Heavy-Clutter-Detection/finalDiffusion/.venv/lib/python3.12/site-packages/urllib3/util/connection.py", line 73, in create_connection
    sock.connect(sa)
ConnectionRefusedError: [Errno 111] Connection refused

The above exception was the direct cause of the following exception:

Traceback (most recent call last):
  File "/home/hawk/Desktop/Heavy-Clutter-Detection/finalDiffusion/.venv/lib/python3.12/site-packages/urllib3/connectionpool.py", line 787, in urlopen
    response = self._make_request(
               ^^^^^^^^^^^^^^^^^^^
  File "/home/hawk/Desktop/Heavy-Clutter-Detection/finalDiffusion/.venv/lib/python3.12/site-packages/urllib3/connectionpool.py", line 493, in _make_request
    conn.request(
  File "/home/hawk/Desktop/Heavy-Clutter-Detection/finalDiffusion/.venv/lib/python3.12/site-packages/urllib3/connection.py", line 445, in request
    self.endheaders()
  File "/usr/lib/python3.12/http/client.py", line 1331, in endheaders
    self._send_output(message_body, encode_chunked=encode_chunked)
  File "/usr/lib/python3.12/http/client.py", line 1091, in _send_output
    self.send(msg)
  File "/usr/lib/python3.12/http/client.py", line 1035, in send
    self.connect()
  File "/home/hawk/Desktop/Heavy-Clutter-Detection/finalDiffusion/.venv/lib/python3.12/site-packages/urllib3/connection.py", line 276, in connect
    self.sock = self._new_conn()
                ^^^^^^^^^^^^^^^^
  File "/home/hawk/Desktop/Heavy-Clutter-Detection/finalDiffusion/.venv/lib/python3.12/site-packages/urllib3/connection.py", line 213, in _new_conn
    raise NewConnectionError(
urllib3.exceptions.NewConnectionError: <urllib3.connection.HTTPConnection object at 0x7cc8fcdf1940>: Failed to establish a new connection: [Errno 111] Connection refused

The above exception was the direct cause of the following exception:

Traceback (most recent call last):
  File "/home/hawk/Desktop/Heavy-Clutter-Detection/finalDiffusion/.venv/lib/python3.12/site-packages/requests/adapters.py", line 667, in send
    resp = conn.urlopen(
           ^^^^^^^^^^^^^
  File "/home/hawk/Desktop/Heavy-Clutter-Detection/finalDiffusion/.venv/lib/python3.12/site-packages/urllib3/connectionpool.py", line 841, in urlopen
    retries = retries.increment(
              ^^^^^^^^^^^^^^^^^^
  File "/home/hawk/Desktop/Heavy-Clutter-Detection/finalDiffusion/.venv/lib/python3.12/site-packages/urllib3/util/retry.py", line 519, in increment
    raise MaxRetryError(_pool, url, reason) from reason  # type: ignore[arg-type]
    ^^^^^^^^^^^^^^^^^^^^^^^^^^^^^^^^^^^^^^^^^^^^^^^^^^^
urllib3.exceptions.MaxRetryError: HTTPConnectionPool(host='127.0.0.1', port=8081): Max retries exceeded with url: /graphql (Caused by NewConnectionError('<urllib3.connection.HTTPConnection object at 0x7cc8fcdf1940>: Failed to establish a new connection: [Errno 111] Connection refused'))

During handling of the above exception, another exception occurred:

Traceback (most recent call last):
  File "/home/hawk/Desktop/Heavy-Clutter-Detection/finalDiffusion/.venv/lib/python3.12/site-packages/wandb/sdk/lib/retry.py", line 134, in __call__
    result = self._call_fn(*args, **kwargs)
             ^^^^^^^^^^^^^^^^^^^^^^^^^^^^^^
  File "/home/hawk/Desktop/Heavy-Clutter-Detection/finalDiffusion/.venv/lib/python3.12/site-packages/wandb/sdk/internal/internal_api.py", line 402, in execute
    return self.client.execute(*args, **kwargs)  # type: ignore
           ^^^^^^^^^^^^^^^^^^^^^^^^^^^^^^^^^^^^
  File "/home/hawk/Desktop/Heavy-Clutter-Detection/finalDiffusion/.venv/lib/python3.12/site-packages/wandb/vendor/gql-0.2.0/wandb_gql/client.py", line 52, in execute
    result = self._get_result(document, *args, **kwargs)
             ^^^^^^^^^^^^^^^^^^^^^^^^^^^^^^^^^^^^^^^^^^^
  File "/home/hawk/Desktop/Heavy-Clutter-Detection/finalDiffusion/.venv/lib/python3.12/site-packages/wandb/vendor/gql-0.2.0/wandb_gql/client.py", line 60, in _get_result
    return self.transport.execute(document, *args, **kwargs)
           ^^^^^^^^^^^^^^^^^^^^^^^^^^^^^^^^^^^^^^^^^^^^^^^^^
  File "/home/hawk/Desktop/Heavy-Clutter-Detection/finalDiffusion/.venv/lib/python3.12/site-packages/wandb/sdk/lib/gql_request.py", line 58, in execute
    request = self.session.post(self.url, **post_args)
              ^^^^^^^^^^^^^^^^^^^^^^^^^^^^^^^^^^^^^^^^
  File "/home/hawk/Desktop/Heavy-Clutter-Detection/finalDiffusion/.venv/lib/python3.12/site-packages/requests/sessions.py", line 637, in post
    return self.request("POST", url, data=data, json=json, **kwargs)
           ^^^^^^^^^^^^^^^^^^^^^^^^^^^^^^^^^^^^^^^^^^^^^^^^^^^^^^^^^
  File "/home/hawk/Desktop/Heavy-Clutter-Detection/finalDiffusion/.venv/lib/python3.12/site-packages/requests/sessions.py", line 589, in request
    resp = self.send(prep, **send_kwargs)
           ^^^^^^^^^^^^^^^^^^^^^^^^^^^^^^
  File "/home/hawk/Desktop/Heavy-Clutter-Detection/finalDiffusion/.venv/lib/python3.12/site-packages/requests/sessions.py", line 703, in send
    r = adapter.send(request, **kwargs)
        ^^^^^^^^^^^^^^^^^^^^^^^^^^^^^^^
  File "/home/hawk/Desktop/Heavy-Clutter-Detection/finalDiffusion/.venv/lib/python3.12/site-packages/requests/adapters.py", line 700, in send
    raise ConnectionError(e, request=request)
requests.exceptions.ConnectionError: HTTPConnectionPool(host='127.0.0.1', port=8081): Max retries exceeded with url: /graphql (Caused by NewConnectionError('<urllib3.connection.HTTPConnection object at 0x7cc8fcdf1940>: Failed to establish a new connection: [Errno 111] Connection refused'))
2025-05-25 11:02:40,969 INFO    Thread-15 (wrapped_target):1182312 [retry.py:__call__():175] [no run ID] Retry attempt failed:
Traceback (most recent call last):
  File "/home/hawk/Desktop/Heavy-Clutter-Detection/finalDiffusion/.venv/lib/python3.12/site-packages/urllib3/connection.py", line 198, in _new_conn
    sock = connection.create_connection(
           ^^^^^^^^^^^^^^^^^^^^^^^^^^^^^
  File "/home/hawk/Desktop/Heavy-Clutter-Detection/finalDiffusion/.venv/lib/python3.12/site-packages/urllib3/util/connection.py", line 85, in create_connection
    raise err
  File "/home/hawk/Desktop/Heavy-Clutter-Detection/finalDiffusion/.venv/lib/python3.12/site-packages/urllib3/util/connection.py", line 73, in create_connection
    sock.connect(sa)
ConnectionRefusedError: [Errno 111] Connection refused

The above exception was the direct cause of the following exception:

Traceback (most recent call last):
  File "/home/hawk/Desktop/Heavy-Clutter-Detection/finalDiffusion/.venv/lib/python3.12/site-packages/urllib3/connectionpool.py", line 787, in urlopen
    response = self._make_request(
               ^^^^^^^^^^^^^^^^^^^
  File "/home/hawk/Desktop/Heavy-Clutter-Detection/finalDiffusion/.venv/lib/python3.12/site-packages/urllib3/connectionpool.py", line 493, in _make_request
    conn.request(
  File "/home/hawk/Desktop/Heavy-Clutter-Detection/finalDiffusion/.venv/lib/python3.12/site-packages/urllib3/connection.py", line 445, in request
    self.endheaders()
  File "/usr/lib/python3.12/http/client.py", line 1331, in endheaders
    self._send_output(message_body, encode_chunked=encode_chunked)
  File "/usr/lib/python3.12/http/client.py", line 1091, in _send_output
    self.send(msg)
  File "/usr/lib/python3.12/http/client.py", line 1035, in send
    self.connect()
  File "/home/hawk/Desktop/Heavy-Clutter-Detection/finalDiffusion/.venv/lib/python3.12/site-packages/urllib3/connection.py", line 276, in connect
    self.sock = self._new_conn()
                ^^^^^^^^^^^^^^^^
  File "/home/hawk/Desktop/Heavy-Clutter-Detection/finalDiffusion/.venv/lib/python3.12/site-packages/urllib3/connection.py", line 213, in _new_conn
    raise NewConnectionError(
urllib3.exceptions.NewConnectionError: <urllib3.connection.HTTPConnection object at 0x7cc8fcdecc20>: Failed to establish a new connection: [Errno 111] Connection refused

The above exception was the direct cause of the following exception:

Traceback (most recent call last):
  File "/home/hawk/Desktop/Heavy-Clutter-Detection/finalDiffusion/.venv/lib/python3.12/site-packages/requests/adapters.py", line 667, in send
    resp = conn.urlopen(
           ^^^^^^^^^^^^^
  File "/home/hawk/Desktop/Heavy-Clutter-Detection/finalDiffusion/.venv/lib/python3.12/site-packages/urllib3/connectionpool.py", line 841, in urlopen
    retries = retries.increment(
              ^^^^^^^^^^^^^^^^^^
  File "/home/hawk/Desktop/Heavy-Clutter-Detection/finalDiffusion/.venv/lib/python3.12/site-packages/urllib3/util/retry.py", line 519, in increment
    raise MaxRetryError(_pool, url, reason) from reason  # type: ignore[arg-type]
    ^^^^^^^^^^^^^^^^^^^^^^^^^^^^^^^^^^^^^^^^^^^^^^^^^^^
urllib3.exceptions.MaxRetryError: HTTPConnectionPool(host='127.0.0.1', port=8081): Max retries exceeded with url: /graphql (Caused by NewConnectionError('<urllib3.connection.HTTPConnection object at 0x7cc8fcdecc20>: Failed to establish a new connection: [Errno 111] Connection refused'))

During handling of the above exception, another exception occurred:

Traceback (most recent call last):
  File "/home/hawk/Desktop/Heavy-Clutter-Detection/finalDiffusion/.venv/lib/python3.12/site-packages/wandb/sdk/lib/retry.py", line 134, in __call__
    result = self._call_fn(*args, **kwargs)
             ^^^^^^^^^^^^^^^^^^^^^^^^^^^^^^
  File "/home/hawk/Desktop/Heavy-Clutter-Detection/finalDiffusion/.venv/lib/python3.12/site-packages/wandb/sdk/internal/internal_api.py", line 402, in execute
    return self.client.execute(*args, **kwargs)  # type: ignore
           ^^^^^^^^^^^^^^^^^^^^^^^^^^^^^^^^^^^^
  File "/home/hawk/Desktop/Heavy-Clutter-Detection/finalDiffusion/.venv/lib/python3.12/site-packages/wandb/vendor/gql-0.2.0/wandb_gql/client.py", line 52, in execute
    result = self._get_result(document, *args, **kwargs)
             ^^^^^^^^^^^^^^^^^^^^^^^^^^^^^^^^^^^^^^^^^^^
  File "/home/hawk/Desktop/Heavy-Clutter-Detection/finalDiffusion/.venv/lib/python3.12/site-packages/wandb/vendor/gql-0.2.0/wandb_gql/client.py", line 60, in _get_result
    return self.transport.execute(document, *args, **kwargs)
           ^^^^^^^^^^^^^^^^^^^^^^^^^^^^^^^^^^^^^^^^^^^^^^^^^
  File "/home/hawk/Desktop/Heavy-Clutter-Detection/finalDiffusion/.venv/lib/python3.12/site-packages/wandb/sdk/lib/gql_request.py", line 58, in execute
    request = self.session.post(self.url, **post_args)
              ^^^^^^^^^^^^^^^^^^^^^^^^^^^^^^^^^^^^^^^^
  File "/home/hawk/Desktop/Heavy-Clutter-Detection/finalDiffusion/.venv/lib/python3.12/site-packages/requests/sessions.py", line 637, in post
    return self.request("POST", url, data=data, json=json, **kwargs)
           ^^^^^^^^^^^^^^^^^^^^^^^^^^^^^^^^^^^^^^^^^^^^^^^^^^^^^^^^^
  File "/home/hawk/Desktop/Heavy-Clutter-Detection/finalDiffusion/.venv/lib/python3.12/site-packages/requests/sessions.py", line 589, in request
    resp = self.send(prep, **send_kwargs)
           ^^^^^^^^^^^^^^^^^^^^^^^^^^^^^^
  File "/home/hawk/Desktop/Heavy-Clutter-Detection/finalDiffusion/.venv/lib/python3.12/site-packages/requests/sessions.py", line 703, in send
    r = adapter.send(request, **kwargs)
        ^^^^^^^^^^^^^^^^^^^^^^^^^^^^^^^
  File "/home/hawk/Desktop/Heavy-Clutter-Detection/finalDiffusion/.venv/lib/python3.12/site-packages/requests/adapters.py", line 700, in send
    raise ConnectionError(e, request=request)
requests.exceptions.ConnectionError: HTTPConnectionPool(host='127.0.0.1', port=8081): Max retries exceeded with url: /graphql (Caused by NewConnectionError('<urllib3.connection.HTTPConnection object at 0x7cc8fcdecc20>: Failed to establish a new connection: [Errno 111] Connection refused'))
2025-05-25 11:02:43,265 ERROR   MainThread:1182312 [wandb_init.py:init():1540] [no run ID] error in wandb.init()
Traceback (most recent call last):
  File "/home/hawk/Desktop/Heavy-Clutter-Detection/finalDiffusion/.venv/lib/python3.12/site-packages/wandb/sdk/wandb_init.py", line 1530, in init
    return wi.init(run_settings, run_config)
           ^^^^^^^^^^^^^^^^^^^^^^^^^^^^^^^^^
  File "/home/hawk/Desktop/Heavy-Clutter-Detection/finalDiffusion/.venv/lib/python3.12/site-packages/wandb/sdk/wandb_init.py", line 922, in init
    backend.interface.publish_header()
  File "/home/hawk/Desktop/Heavy-Clutter-Detection/finalDiffusion/.venv/lib/python3.12/site-packages/wandb/sdk/interface/interface.py", line 97, in publish_header
    self._publish_header(header)
  File "/home/hawk/Desktop/Heavy-Clutter-Detection/finalDiffusion/.venv/lib/python3.12/site-packages/wandb/sdk/interface/interface_shared.py", line 275, in _publish_header
    self._publish(rec)
  File "/home/hawk/Desktop/Heavy-Clutter-Detection/finalDiffusion/.venv/lib/python3.12/site-packages/wandb/sdk/interface/interface_sock.py", line 39, in _publish
    self._sock_client.send_record_publish(record)
  File "/home/hawk/Desktop/Heavy-Clutter-Detection/finalDiffusion/.venv/lib/python3.12/site-packages/wandb/sdk/lib/sock_client.py", line 174, in send_record_publish
    self.send_server_request(server_req)
  File "/home/hawk/Desktop/Heavy-Clutter-Detection/finalDiffusion/.venv/lib/python3.12/site-packages/wandb/sdk/lib/sock_client.py", line 154, in send_server_request
    self._send_message(msg)
  File "/home/hawk/Desktop/Heavy-Clutter-Detection/finalDiffusion/.venv/lib/python3.12/site-packages/wandb/sdk/lib/sock_client.py", line 151, in _send_message
    self._sendall_with_error_handle(header + data)
  File "/home/hawk/Desktop/Heavy-Clutter-Detection/finalDiffusion/.venv/lib/python3.12/site-packages/wandb/sdk/lib/sock_client.py", line 130, in _sendall_with_error_handle
    sent = self._sock.send(data)
           ^^^^^^^^^^^^^^^^^^^^^
BrokenPipeError: [Errno 32] Broken pipe
2025-05-25 11:03:40,190 INFO    Thread-17 (wrapped_target):1182312 [retry.py:__call__():175] [no run ID] Retry attempt failed:
Traceback (most recent call last):
  File "/home/hawk/Desktop/Heavy-Clutter-Detection/finalDiffusion/.venv/lib/python3.12/site-packages/urllib3/connection.py", line 198, in _new_conn
    sock = connection.create_connection(
           ^^^^^^^^^^^^^^^^^^^^^^^^^^^^^
  File "/home/hawk/Desktop/Heavy-Clutter-Detection/finalDiffusion/.venv/lib/python3.12/site-packages/urllib3/util/connection.py", line 85, in create_connection
    raise err
  File "/home/hawk/Desktop/Heavy-Clutter-Detection/finalDiffusion/.venv/lib/python3.12/site-packages/urllib3/util/connection.py", line 73, in create_connection
    sock.connect(sa)
ConnectionRefusedError: [Errno 111] Connection refused

The above exception was the direct cause of the following exception:

Traceback (most recent call last):
  File "/home/hawk/Desktop/Heavy-Clutter-Detection/finalDiffusion/.venv/lib/python3.12/site-packages/urllib3/connectionpool.py", line 787, in urlopen
    response = self._make_request(
               ^^^^^^^^^^^^^^^^^^^
  File "/home/hawk/Desktop/Heavy-Clutter-Detection/finalDiffusion/.venv/lib/python3.12/site-packages/urllib3/connectionpool.py", line 493, in _make_request
    conn.request(
  File "/home/hawk/Desktop/Heavy-Clutter-Detection/finalDiffusion/.venv/lib/python3.12/site-packages/urllib3/connection.py", line 445, in request
    self.endheaders()
  File "/usr/lib/python3.12/http/client.py", line 1331, in endheaders
    self._send_output(message_body, encode_chunked=encode_chunked)
  File "/usr/lib/python3.12/http/client.py", line 1091, in _send_output
    self.send(msg)
  File "/usr/lib/python3.12/http/client.py", line 1035, in send
    self.connect()
  File "/home/hawk/Desktop/Heavy-Clutter-Detection/finalDiffusion/.venv/lib/python3.12/site-packages/urllib3/connection.py", line 276, in connect
    self.sock = self._new_conn()
                ^^^^^^^^^^^^^^^^
  File "/home/hawk/Desktop/Heavy-Clutter-Detection/finalDiffusion/.venv/lib/python3.12/site-packages/urllib3/connection.py", line 213, in _new_conn
    raise NewConnectionError(
urllib3.exceptions.NewConnectionError: <urllib3.connection.HTTPConnection object at 0x7cc8fc0d7230>: Failed to establish a new connection: [Errno 111] Connection refused

The above exception was the direct cause of the following exception:

Traceback (most recent call last):
  File "/home/hawk/Desktop/Heavy-Clutter-Detection/finalDiffusion/.venv/lib/python3.12/site-packages/requests/adapters.py", line 667, in send
    resp = conn.urlopen(
           ^^^^^^^^^^^^^
  File "/home/hawk/Desktop/Heavy-Clutter-Detection/finalDiffusion/.venv/lib/python3.12/site-packages/urllib3/connectionpool.py", line 841, in urlopen
    retries = retries.increment(
              ^^^^^^^^^^^^^^^^^^
  File "/home/hawk/Desktop/Heavy-Clutter-Detection/finalDiffusion/.venv/lib/python3.12/site-packages/urllib3/util/retry.py", line 519, in increment
    raise MaxRetryError(_pool, url, reason) from reason  # type: ignore[arg-type]
    ^^^^^^^^^^^^^^^^^^^^^^^^^^^^^^^^^^^^^^^^^^^^^^^^^^^
urllib3.exceptions.MaxRetryError: HTTPConnectionPool(host='127.0.0.1', port=8081): Max retries exceeded with url: /graphql (Caused by NewConnectionError('<urllib3.connection.HTTPConnection object at 0x7cc8fc0d7230>: Failed to establish a new connection: [Errno 111] Connection refused'))

During handling of the above exception, another exception occurred:

Traceback (most recent call last):
  File "/home/hawk/Desktop/Heavy-Clutter-Detection/finalDiffusion/.venv/lib/python3.12/site-packages/wandb/sdk/lib/retry.py", line 134, in __call__
    result = self._call_fn(*args, **kwargs)
             ^^^^^^^^^^^^^^^^^^^^^^^^^^^^^^
  File "/home/hawk/Desktop/Heavy-Clutter-Detection/finalDiffusion/.venv/lib/python3.12/site-packages/wandb/sdk/internal/internal_api.py", line 402, in execute
    return self.client.execute(*args, **kwargs)  # type: ignore
           ^^^^^^^^^^^^^^^^^^^^^^^^^^^^^^^^^^^^
  File "/home/hawk/Desktop/Heavy-Clutter-Detection/finalDiffusion/.venv/lib/python3.12/site-packages/wandb/vendor/gql-0.2.0/wandb_gql/client.py", line 52, in execute
    result = self._get_result(document, *args, **kwargs)
             ^^^^^^^^^^^^^^^^^^^^^^^^^^^^^^^^^^^^^^^^^^^
  File "/home/hawk/Desktop/Heavy-Clutter-Detection/finalDiffusion/.venv/lib/python3.12/site-packages/wandb/vendor/gql-0.2.0/wandb_gql/client.py", line 60, in _get_result
    return self.transport.execute(document, *args, **kwargs)
           ^^^^^^^^^^^^^^^^^^^^^^^^^^^^^^^^^^^^^^^^^^^^^^^^^
  File "/home/hawk/Desktop/Heavy-Clutter-Detection/finalDiffusion/.venv/lib/python3.12/site-packages/wandb/sdk/lib/gql_request.py", line 58, in execute
    request = self.session.post(self.url, **post_args)
              ^^^^^^^^^^^^^^^^^^^^^^^^^^^^^^^^^^^^^^^^
  File "/home/hawk/Desktop/Heavy-Clutter-Detection/finalDiffusion/.venv/lib/python3.12/site-packages/requests/sessions.py", line 637, in post
    return self.request("POST", url, data=data, json=json, **kwargs)
           ^^^^^^^^^^^^^^^^^^^^^^^^^^^^^^^^^^^^^^^^^^^^^^^^^^^^^^^^^
  File "/home/hawk/Desktop/Heavy-Clutter-Detection/finalDiffusion/.venv/lib/python3.12/site-packages/requests/sessions.py", line 589, in request
    resp = self.send(prep, **send_kwargs)
           ^^^^^^^^^^^^^^^^^^^^^^^^^^^^^^
  File "/home/hawk/Desktop/Heavy-Clutter-Detection/finalDiffusion/.venv/lib/python3.12/site-packages/requests/sessions.py", line 703, in send
    r = adapter.send(request, **kwargs)
        ^^^^^^^^^^^^^^^^^^^^^^^^^^^^^^^
  File "/home/hawk/Desktop/Heavy-Clutter-Detection/finalDiffusion/.venv/lib/python3.12/site-packages/requests/adapters.py", line 700, in send
    raise ConnectionError(e, request=request)
requests.exceptions.ConnectionError: HTTPConnectionPool(host='127.0.0.1', port=8081): Max retries exceeded with url: /graphql (Caused by NewConnectionError('<urllib3.connection.HTTPConnection object at 0x7cc8fc0d7230>: Failed to establish a new connection: [Errno 111] Connection refused'))
2025-05-25 11:03:44,217 INFO    Thread-17 (wrapped_target):1182312 [retry.py:__call__():175] [no run ID] Retry attempt failed:
Traceback (most recent call last):
  File "/home/hawk/Desktop/Heavy-Clutter-Detection/finalDiffusion/.venv/lib/python3.12/site-packages/urllib3/connection.py", line 198, in _new_conn
    sock = connection.create_connection(
           ^^^^^^^^^^^^^^^^^^^^^^^^^^^^^
  File "/home/hawk/Desktop/Heavy-Clutter-Detection/finalDiffusion/.venv/lib/python3.12/site-packages/urllib3/util/connection.py", line 85, in create_connection
    raise err
  File "/home/hawk/Desktop/Heavy-Clutter-Detection/finalDiffusion/.venv/lib/python3.12/site-packages/urllib3/util/connection.py", line 73, in create_connection
    sock.connect(sa)
ConnectionRefusedError: [Errno 111] Connection refused

The above exception was the direct cause of the following exception:

Traceback (most recent call last):
  File "/home/hawk/Desktop/Heavy-Clutter-Detection/finalDiffusion/.venv/lib/python3.12/site-packages/urllib3/connectionpool.py", line 787, in urlopen
    response = self._make_request(
               ^^^^^^^^^^^^^^^^^^^
  File "/home/hawk/Desktop/Heavy-Clutter-Detection/finalDiffusion/.venv/lib/python3.12/site-packages/urllib3/connectionpool.py", line 493, in _make_request
    conn.request(
  File "/home/hawk/Desktop/Heavy-Clutter-Detection/finalDiffusion/.venv/lib/python3.12/site-packages/urllib3/connection.py", line 445, in request
    self.endheaders()
  File "/usr/lib/python3.12/http/client.py", line 1331, in endheaders
    self._send_output(message_body, encode_chunked=encode_chunked)
  File "/usr/lib/python3.12/http/client.py", line 1091, in _send_output
    self.send(msg)
  File "/usr/lib/python3.12/http/client.py", line 1035, in send
    self.connect()
  File "/home/hawk/Desktop/Heavy-Clutter-Detection/finalDiffusion/.venv/lib/python3.12/site-packages/urllib3/connection.py", line 276, in connect
    self.sock = self._new_conn()
                ^^^^^^^^^^^^^^^^
  File "/home/hawk/Desktop/Heavy-Clutter-Detection/finalDiffusion/.venv/lib/python3.12/site-packages/urllib3/connection.py", line 213, in _new_conn
    raise NewConnectionError(
urllib3.exceptions.NewConnectionError: <urllib3.connection.HTTPConnection object at 0x7cc8fc0db4d0>: Failed to establish a new connection: [Errno 111] Connection refused

The above exception was the direct cause of the following exception:

Traceback (most recent call last):
  File "/home/hawk/Desktop/Heavy-Clutter-Detection/finalDiffusion/.venv/lib/python3.12/site-packages/requests/adapters.py", line 667, in send
    resp = conn.urlopen(
           ^^^^^^^^^^^^^
  File "/home/hawk/Desktop/Heavy-Clutter-Detection/finalDiffusion/.venv/lib/python3.12/site-packages/urllib3/connectionpool.py", line 841, in urlopen
    retries = retries.increment(
              ^^^^^^^^^^^^^^^^^^
  File "/home/hawk/Desktop/Heavy-Clutter-Detection/finalDiffusion/.venv/lib/python3.12/site-packages/urllib3/util/retry.py", line 519, in increment
    raise MaxRetryError(_pool, url, reason) from reason  # type: ignore[arg-type]
    ^^^^^^^^^^^^^^^^^^^^^^^^^^^^^^^^^^^^^^^^^^^^^^^^^^^
urllib3.exceptions.MaxRetryError: HTTPConnectionPool(host='127.0.0.1', port=8081): Max retries exceeded with url: /graphql (Caused by NewConnectionError('<urllib3.connection.HTTPConnection object at 0x7cc8fc0db4d0>: Failed to establish a new connection: [Errno 111] Connection refused'))

During handling of the above exception, another exception occurred:

Traceback (most recent call last):
  File "/home/hawk/Desktop/Heavy-Clutter-Detection/finalDiffusion/.venv/lib/python3.12/site-packages/wandb/sdk/lib/retry.py", line 134, in __call__
    result = self._call_fn(*args, **kwargs)
             ^^^^^^^^^^^^^^^^^^^^^^^^^^^^^^
  File "/home/hawk/Desktop/Heavy-Clutter-Detection/finalDiffusion/.venv/lib/python3.12/site-packages/wandb/sdk/internal/internal_api.py", line 402, in execute
    return self.client.execute(*args, **kwargs)  # type: ignore
           ^^^^^^^^^^^^^^^^^^^^^^^^^^^^^^^^^^^^
  File "/home/hawk/Desktop/Heavy-Clutter-Detection/finalDiffusion/.venv/lib/python3.12/site-packages/wandb/vendor/gql-0.2.0/wandb_gql/client.py", line 52, in execute
    result = self._get_result(document, *args, **kwargs)
             ^^^^^^^^^^^^^^^^^^^^^^^^^^^^^^^^^^^^^^^^^^^
  File "/home/hawk/Desktop/Heavy-Clutter-Detection/finalDiffusion/.venv/lib/python3.12/site-packages/wandb/vendor/gql-0.2.0/wandb_gql/client.py", line 60, in _get_result
    return self.transport.execute(document, *args, **kwargs)
           ^^^^^^^^^^^^^^^^^^^^^^^^^^^^^^^^^^^^^^^^^^^^^^^^^
  File "/home/hawk/Desktop/Heavy-Clutter-Detection/finalDiffusion/.venv/lib/python3.12/site-packages/wandb/sdk/lib/gql_request.py", line 58, in execute
    request = self.session.post(self.url, **post_args)
              ^^^^^^^^^^^^^^^^^^^^^^^^^^^^^^^^^^^^^^^^
  File "/home/hawk/Desktop/Heavy-Clutter-Detection/finalDiffusion/.venv/lib/python3.12/site-packages/requests/sessions.py", line 637, in post
    return self.request("POST", url, data=data, json=json, **kwargs)
           ^^^^^^^^^^^^^^^^^^^^^^^^^^^^^^^^^^^^^^^^^^^^^^^^^^^^^^^^^
  File "/home/hawk/Desktop/Heavy-Clutter-Detection/finalDiffusion/.venv/lib/python3.12/site-packages/requests/sessions.py", line 589, in request
    resp = self.send(prep, **send_kwargs)
           ^^^^^^^^^^^^^^^^^^^^^^^^^^^^^^
  File "/home/hawk/Desktop/Heavy-Clutter-Detection/finalDiffusion/.venv/lib/python3.12/site-packages/requests/sessions.py", line 703, in send
    r = adapter.send(request, **kwargs)
        ^^^^^^^^^^^^^^^^^^^^^^^^^^^^^^^
  File "/home/hawk/Desktop/Heavy-Clutter-Detection/finalDiffusion/.venv/lib/python3.12/site-packages/requests/adapters.py", line 700, in send
    raise ConnectionError(e, request=request)
requests.exceptions.ConnectionError: HTTPConnectionPool(host='127.0.0.1', port=8081): Max retries exceeded with url: /graphql (Caused by NewConnectionError('<urllib3.connection.HTTPConnection object at 0x7cc8fc0db4d0>: Failed to establish a new connection: [Errno 111] Connection refused'))
2025-05-25 11:03:49,108 INFO    Thread-18 (wrapped_target):1182312 [retry.py:__call__():175] [no run ID] Retry attempt failed:
Traceback (most recent call last):
  File "/home/hawk/Desktop/Heavy-Clutter-Detection/finalDiffusion/.venv/lib/python3.12/site-packages/urllib3/connection.py", line 198, in _new_conn
    sock = connection.create_connection(
           ^^^^^^^^^^^^^^^^^^^^^^^^^^^^^
  File "/home/hawk/Desktop/Heavy-Clutter-Detection/finalDiffusion/.venv/lib/python3.12/site-packages/urllib3/util/connection.py", line 85, in create_connection
    raise err
  File "/home/hawk/Desktop/Heavy-Clutter-Detection/finalDiffusion/.venv/lib/python3.12/site-packages/urllib3/util/connection.py", line 73, in create_connection
    sock.connect(sa)
ConnectionRefusedError: [Errno 111] Connection refused

The above exception was the direct cause of the following exception:

Traceback (most recent call last):
  File "/home/hawk/Desktop/Heavy-Clutter-Detection/finalDiffusion/.venv/lib/python3.12/site-packages/urllib3/connectionpool.py", line 787, in urlopen
    response = self._make_request(
               ^^^^^^^^^^^^^^^^^^^
  File "/home/hawk/Desktop/Heavy-Clutter-Detection/finalDiffusion/.venv/lib/python3.12/site-packages/urllib3/connectionpool.py", line 493, in _make_request
    conn.request(
  File "/home/hawk/Desktop/Heavy-Clutter-Detection/finalDiffusion/.venv/lib/python3.12/site-packages/urllib3/connection.py", line 445, in request
    self.endheaders()
  File "/usr/lib/python3.12/http/client.py", line 1331, in endheaders
    self._send_output(message_body, encode_chunked=encode_chunked)
  File "/usr/lib/python3.12/http/client.py", line 1091, in _send_output
    self.send(msg)
  File "/usr/lib/python3.12/http/client.py", line 1035, in send
    self.connect()
  File "/home/hawk/Desktop/Heavy-Clutter-Detection/finalDiffusion/.venv/lib/python3.12/site-packages/urllib3/connection.py", line 276, in connect
    self.sock = self._new_conn()
                ^^^^^^^^^^^^^^^^
  File "/home/hawk/Desktop/Heavy-Clutter-Detection/finalDiffusion/.venv/lib/python3.12/site-packages/urllib3/connection.py", line 213, in _new_conn
    raise NewConnectionError(
urllib3.exceptions.NewConnectionError: <urllib3.connection.HTTPConnection object at 0x7cc8fc0dbdd0>: Failed to establish a new connection: [Errno 111] Connection refused

The above exception was the direct cause of the following exception:

Traceback (most recent call last):
  File "/home/hawk/Desktop/Heavy-Clutter-Detection/finalDiffusion/.venv/lib/python3.12/site-packages/requests/adapters.py", line 667, in send
    resp = conn.urlopen(
           ^^^^^^^^^^^^^
  File "/home/hawk/Desktop/Heavy-Clutter-Detection/finalDiffusion/.venv/lib/python3.12/site-packages/urllib3/connectionpool.py", line 841, in urlopen
    retries = retries.increment(
              ^^^^^^^^^^^^^^^^^^
  File "/home/hawk/Desktop/Heavy-Clutter-Detection/finalDiffusion/.venv/lib/python3.12/site-packages/urllib3/util/retry.py", line 519, in increment
    raise MaxRetryError(_pool, url, reason) from reason  # type: ignore[arg-type]
    ^^^^^^^^^^^^^^^^^^^^^^^^^^^^^^^^^^^^^^^^^^^^^^^^^^^
urllib3.exceptions.MaxRetryError: HTTPConnectionPool(host='127.0.0.1', port=8081): Max retries exceeded with url: /graphql (Caused by NewConnectionError('<urllib3.connection.HTTPConnection object at 0x7cc8fc0dbdd0>: Failed to establish a new connection: [Errno 111] Connection refused'))

During handling of the above exception, another exception occurred:

Traceback (most recent call last):
  File "/home/hawk/Desktop/Heavy-Clutter-Detection/finalDiffusion/.venv/lib/python3.12/site-packages/wandb/sdk/lib/retry.py", line 134, in __call__
    result = self._call_fn(*args, **kwargs)
             ^^^^^^^^^^^^^^^^^^^^^^^^^^^^^^
  File "/home/hawk/Desktop/Heavy-Clutter-Detection/finalDiffusion/.venv/lib/python3.12/site-packages/wandb/sdk/internal/internal_api.py", line 402, in execute
    return self.client.execute(*args, **kwargs)  # type: ignore
           ^^^^^^^^^^^^^^^^^^^^^^^^^^^^^^^^^^^^
  File "/home/hawk/Desktop/Heavy-Clutter-Detection/finalDiffusion/.venv/lib/python3.12/site-packages/wandb/vendor/gql-0.2.0/wandb_gql/client.py", line 52, in execute
    result = self._get_result(document, *args, **kwargs)
             ^^^^^^^^^^^^^^^^^^^^^^^^^^^^^^^^^^^^^^^^^^^
  File "/home/hawk/Desktop/Heavy-Clutter-Detection/finalDiffusion/.venv/lib/python3.12/site-packages/wandb/vendor/gql-0.2.0/wandb_gql/client.py", line 60, in _get_result
    return self.transport.execute(document, *args, **kwargs)
           ^^^^^^^^^^^^^^^^^^^^^^^^^^^^^^^^^^^^^^^^^^^^^^^^^
  File "/home/hawk/Desktop/Heavy-Clutter-Detection/finalDiffusion/.venv/lib/python3.12/site-packages/wandb/sdk/lib/gql_request.py", line 58, in execute
    request = self.session.post(self.url, **post_args)
              ^^^^^^^^^^^^^^^^^^^^^^^^^^^^^^^^^^^^^^^^
  File "/home/hawk/Desktop/Heavy-Clutter-Detection/finalDiffusion/.venv/lib/python3.12/site-packages/requests/sessions.py", line 637, in post
    return self.request("POST", url, data=data, json=json, **kwargs)
           ^^^^^^^^^^^^^^^^^^^^^^^^^^^^^^^^^^^^^^^^^^^^^^^^^^^^^^^^^
  File "/home/hawk/Desktop/Heavy-Clutter-Detection/finalDiffusion/.venv/lib/python3.12/site-packages/requests/sessions.py", line 589, in request
    resp = self.send(prep, **send_kwargs)
           ^^^^^^^^^^^^^^^^^^^^^^^^^^^^^^
  File "/home/hawk/Desktop/Heavy-Clutter-Detection/finalDiffusion/.venv/lib/python3.12/site-packages/requests/sessions.py", line 703, in send
    r = adapter.send(request, **kwargs)
        ^^^^^^^^^^^^^^^^^^^^^^^^^^^^^^^
  File "/home/hawk/Desktop/Heavy-Clutter-Detection/finalDiffusion/.venv/lib/python3.12/site-packages/requests/adapters.py", line 700, in send
    raise ConnectionError(e, request=request)
requests.exceptions.ConnectionError: HTTPConnectionPool(host='127.0.0.1', port=8081): Max retries exceeded with url: /graphql (Caused by NewConnectionError('<urllib3.connection.HTTPConnection object at 0x7cc8fc0dbdd0>: Failed to establish a new connection: [Errno 111] Connection refused'))
2025-05-25 11:03:51,529 ERROR   MainThread:1182312 [wandb_init.py:init():1540] [no run ID] error in wandb.init()
Traceback (most recent call last):
  File "/home/hawk/Desktop/Heavy-Clutter-Detection/finalDiffusion/.venv/lib/python3.12/site-packages/wandb/sdk/wandb_init.py", line 1530, in init
    return wi.init(run_settings, run_config)
           ^^^^^^^^^^^^^^^^^^^^^^^^^^^^^^^^^
  File "/home/hawk/Desktop/Heavy-Clutter-Detection/finalDiffusion/.venv/lib/python3.12/site-packages/wandb/sdk/wandb_init.py", line 814, in init
    service.inform_init(
  File "/home/hawk/Desktop/Heavy-Clutter-Detection/finalDiffusion/.venv/lib/python3.12/site-packages/wandb/sdk/lib/service_connection.py", line 151, in inform_init
    self._client.send_server_request(spb.ServerRequest(inform_init=request))
  File "/home/hawk/Desktop/Heavy-Clutter-Detection/finalDiffusion/.venv/lib/python3.12/site-packages/wandb/sdk/lib/sock_client.py", line 154, in send_server_request
    self._send_message(msg)
  File "/home/hawk/Desktop/Heavy-Clutter-Detection/finalDiffusion/.venv/lib/python3.12/site-packages/wandb/sdk/lib/sock_client.py", line 151, in _send_message
    self._sendall_with_error_handle(header + data)
  File "/home/hawk/Desktop/Heavy-Clutter-Detection/finalDiffusion/.venv/lib/python3.12/site-packages/wandb/sdk/lib/sock_client.py", line 130, in _sendall_with_error_handle
    sent = self._sock.send(data)
           ^^^^^^^^^^^^^^^^^^^^^
BrokenPipeError: [Errno 32] Broken pipe
